Workbook

Sheet Dashboard
B2: E-COMMERCE BUDGET & TRACKING FRAMEWORK
B3: 5-Site Portfolio | 12-Month Projection | Industry Benchmark Aligned
B4: Created: January 28, 2026
B6: PORTFOLIO OVERVIEW
B8: GTSE.co.uk | F8: GTSEGroup.com | J8: SafetySignHub.co.uk
B9: Market: UK Market | F9: Market: Global | J9: Market: UK Market
B10: Focus: B2B Safety Signs | F10: Focus: Corporate Portal | J10: Focus: B2C Safety Signs
B11: Status: Mature | F11: Status: Launch | J11: Status: Growth
B14: SafetySignHub.com | F14: Epha.com
B15: Market: USA Market | F15: Market: Global
B16: Focus: B2C Safety Signs | F16: Focus: Premium Safety Equipment
B17: Status: Launch | F17: Status: Beta
B20: WORKBOOK NAVIGATION
B22: Dashboard | D22: Executive summary and key metrics overview
B23: Assumptions | D23: Industry benchmarks and adjustable KPI assumptions
B24: GTSE.co.uk | D24: UK B2B site - 12-month financial projection
B25: GTSEGroup.com | D25: Global corporate portal - launch projections
B26: SSH UK | D26: UK B2C site - growth trajectory
B27: SSH USA | D27: USA B2C site - market entry plan
B28: Epha.com | D28: Premium equipment - beta to launch
B29: Consolidated | D29: Portfolio-wide aggregated view
B30: Operations | D30: Team structure, costs, and milestones
B31: Glossary | D31: E-commerce metrics explained
B34: 12-MONTH PORTFOLIO TARGETS (Consolidated)
B36: Total Revenue | D36: £1,847,500 | F36: Based on industry benchmarks
B37: Total Orders | D37: 18,450 | F37: Across all 5 sites
B38: Marketing Spend | D38: £485,000 | F38: Paid + operational
B39: Gross Profit | D39: £739,000 | F39: 40% average margin
B40: Portfolio ROAS | D40: 3.8x | F40: Return on ad spend
B41: Break-even Month | D41: Month 7 | F41: Epha.com extends timeline
B44: IMPORTANT NOTES
B46: • Blue text = Input/Assumption values (editable)
B47: • Black text = Calculated values (formulas)
B48: • All currency values in GBP (£) unless noted
B49: • Assumptions based on e-commerce industry benchmarks (see Assumptions sheet)
B50: • Monthly review recommended - update actuals vs projections

Sheet Assumptions
B2: ASSUMPTIONS & INDUSTRY BENCHMARKS
B3: Adjust these values to model different scenarios. All projections flow from these assumptions.
B5: TRAFFIC ASSUMPTIONS
B7: Metric | C7: GTSE.co.uk | D7: GTSEGroup.com | E7: SSH UK | F7: SSH USA | G7: Epha.com | H7: Notes / Source
B8: Starting Organic Traffic (M1) | C8: 800 | D8: 200 | E8: 500 | F8: 300 | G8: 150 | H8: Industry: 300-1000 for new sites
B9: Organic Growth Rate (MoM) | C9: 0.04 | D9: 0.15 | E9: 0.08 | F9: 0.15 | G9: 0.2 | H9: Stress Test: Conservative SEO Ramps
B10: Starting Paid Traffic (M1) | C10: 1200 | D10: 800 | E10: 1000 | F10: 1500 | G10: 600 | H10: Based on initial ad budget
B11: Paid Growth Rate (MoM) | C11: 0.05 | D11: 0.1 | E11: 0.08 | F11: 0.12 | G11: 0.1 | H11: Stress Test: Scale with Margin
B12: Direct/Referral Traffic (M1) | C12: 300 | D12: 100 | E12: 200 | F12: 150 | G12: 80 | H12: Brand awareness baseline
B13: Direct Growth Rate (MoM) | C13: 5% | D13: 8% | E13: 6% | F13: 10% | G13: 12% | H13: Brand building over time
B15: CONVERSION & REVENUE ASSUMPTIONS
B17: Metric | C17: GTSE.co.uk | D17: GTSEGroup.com | E17: SSH UK | F17: SSH USA | G17: Epha.com | H17: Notes / Source
B18: Starting Conversion Rate (M1) | C18: 2.0% | D18: 1.5% | E18: 2.2% | F18: 2.0% | G18: 1.8% | H18: Industry avg: 1.5-3% B2C, 2-4% B2B
B19: Conversion Improvement (MoM) | C19: 0.1% | D19: 0.15% | E19: 0.1% | F19: 0.12% | G19: 0.15% | H19: CRO optimization
B20: Max Conversion Rate | C20: 3.5% | D20: 3.0% | E20: 3.8% | F20: 3.5% | G20: 3.2% | H20: Realistic ceiling
B21: Average Order Value (AOV) - M1 | C21: 85 | D21: 250 | E21: 75 | F21: 90 | G21: 120 | H21: B2B higher than B2C
B22: AOV Growth (MoM) | C22: 0.005 | D22: 0.01 | E22: 0.005 | F22: 0.01 | G22: 0.01 | H22: Stress Test: Incremental Upselling
B23: Gross Margin | C23: 40% | D23: 45% | E23: 38% | F23: 40% | G23: 50% | H23: Industry: 30-50%
B24: Distribution Cost % | C24: 20% | D24: 15% | E24: 22% | F24: 20% | G24: 18% | H24: Shipping + fulfillment
B26: MARKETING SPEND ASSUMPTIONS
B28: Metric | C28: GTSE.co.uk | D28: GTSEGroup.com | E28: SSH UK | F28: SSH USA | G28: Epha.com | H28: Notes / Source
B29: Starting Paid Spend (M1) | C29: 2500 | D29: 1500 | E29: 2000 | F29: 3000 | G29: 1200 | H29: Google Ads + Social
B30: Paid Spend Growth (MoM) | C30: 0.05 | D30: 0.1 | E30: 0.08 | F30: 0.12 | G30: 0.1 | H30: Scale with performance
B31: Cost Per Click (CPC) - M1 | C31: 2.08 | D31: 1.88 | E31: 2 | F31: 2 | G31: 2 | H31: Industry benchmark
B32: CPC Trend (MoM) | C32: 0.005 | D32: 0.005 | E32: 0.005 | F32: 0.005 | G32: 0.005 | H32: Stress Test: Competitive Inflation
B33: SEO Investment (Monthly) | C33: 800 | D33: 1200 | E33: 1000 | F33: 1500 | G33: 1000 | H33: Content + technical
B34: Email Marketing (Monthly) | C34: 300 | D34: 200 | E34: 400 | F34: 500 | G34: 300 | H34: Platform + creative
B35: Influencer/Affiliate (Monthly) | C35: 0 | D35: 0 | E35: 500 | F35: 800 | G35: 400 | H35: SSH USA focus
B37: OPERATIONAL COSTS (Monthly)
B39: Metric | C39: GTSE.co.uk | D39: GTSEGroup.com | E39: SSH UK | F39: SSH USA | G39: Epha.com | H39: Notes / Source
B40: Platform/Hosting Fees | C40: 200 | D40: 150 | E40: 180 | F40: 180 | G40: 250 | H40: Shopify/Custom hosting
B41: Payment Processing % | C41: 2.5% | D41: 2.5% | E41: 2.9% | F41: 2.9% | G41: 2.5% | H41: Stripe/PayPal rates
B42: Customer Service (Staff) | C42: 1500 | D42: 800 | E42: 1200 | F42: 1500 | G42: 1000 | H42: Part-time to full-time
B43: Software/Tools | C43: 300 | D43: 400 | E43: 350 | F43: 350 | G43: 400 | H43: Analytics, CRM, etc.
B44: Content Production | C44: 500 | D44: 800 | E44: 600 | F44: 800 | G44: 700 | H44: Photography, copywriting
B47: INDUSTRY BENCHMARKS REFERENCE
B49: Metric | C49: Poor | D49: Average | E49: Good | F49: Excellent | G49: Source
B50: E-commerce Conversion Rate | C50: <1% | D50: 1.5-2.5% | E50: 2.5-4% | F50: >4% | G50: IRP Commerce, 2024
B51: B2B Conversion Rate | C51: <2% | D51: 2-3% | E51: 3-5% | F51: >5% | G51: HubSpot, 2024
B52: Return on Ad Spend (ROAS) | C52: <2x | D52: 2-3x | E52: 3-5x | F52: >5x | G52: WordStream, 2024
...

Sheet GTSE.co.uk
B2: GTSE.co.uk - 12 MONTH PROJECTION
B3: Market: UK B2B | Status: Mature | Currency: GBP (£)
B5: METRIC | C5: M1 | D5: M2 | E5: M3 | F5: M4 | G5: M5 | H5: M6 | I5: M7 | J5: M8 | K5: M9 | L5: M10 | M5: M11 | N5: M12
B7: KEY ASSUMPTIONS (Editable)
B8: Starting Organic Traffic | C8: 800 | D8: visitors
B9: Organic Growth Rate | C9: 0.04 | D9: decimal
B10: Starting Paid Traffic | C10: 1200 | D10: visitors
B11: Paid Growth Rate | C11: 0.05 | D11: decimal
B12: Starting Conversion Rate | C12: 0.02 | D12: decimal
B13: Conv. Rate Improvement | C13: 0.001 | D13: decimal
B14: Max Conversion Rate | C14: 0.035 | D14: decimal
B15: Average Order Value | C15: 85 | D15: currency
B16: AOV Growth Rate | C16: 0.005 | D16: decimal
B17: Gross Margin | C17: 0.4 | D17: decimal
B18: Distribution Cost % | C18: 0.2 | D18: decimal
B19: Starting Ad Spend | C19: 2500 | D19: currency
... B21: Cost Per Click | C21: 2.08 | D21: currency
B23: TRAFFIC
B24: Organic Traffic | C24: =C8 | D24: =C24*(1+$C9) | E24: =D24*(1+$C9) | F24: =E24*(1+$C9) | G24: =F24*(1+$C9) | H24: =G24*(1+$C9) | I24: =H24*(1+$C9) | J24: =I24*(1+$C9) | K24: =J24*(1+$C9) | ... N24: =M24*(1+$C9)
B25: Paid Traffic | C25: =C10 | D25: =C25*(1+$C11) | E25: =D25*(1+$C11) | F25: =E25*(1+$C11) | G25: =F25*(1+$C11) | H25: =G25*(1+$C11) | I25: =H25*(1+$C11) | J25: =I25*(1+$C11) | K25: =J25*(1+$C11) | ... N25: =M25*(1+$C11)
B26: Direct/Referral Traffic | C26: =C24*0.25 | D26: =D24*0.25 | E26: =E24*0.25 | F26: =F24*0.25 | G26: =G24*0.25 | H26: =H24*0.25 | I26: =I24*0.25 | J26: =J24*0.25 | ... N26: =N24*0.25
B27: TOTAL TRAFFIC | C27: =C24+C25+C26 | D27: =D24+D25+D26 | E27: =E24+E25+E26 | F27: =F24+F25+F26 | G27: =G24+G25+G26 | H27: =H24+H25+H26 | I27: =I24+I25+I26 | J27: =J24+J25+J26 | ... N27: =N24+N25+N26
B29: CONVERSION
B30: Conversion Rate | C30: =C12 | D30: =MIN(C30+$C13,$C14) | E30: =MIN(D30+$C13,$C14) | F30: =MIN(E30+$C13,$C14) | G30: =MIN(F30+$C13,$C14) | H30: =MIN(G30+$C13,$C14) | I30: =MIN(H30+$C13,$C14) | J30: =MIN(I30+$C13,$C14) | K30: =MIN(J30+$C13,$C14) | ... N30: =MIN(M30+$C13,$C14)
B31: Orders | C31: =C27*C30 | D31: =D27*D30 | E31: =E27*E30 | F31: =F27*F30 | G31: =G27*G30 | H31: =H27*H30 | I31: =I27*I30 | J31: =J27*J30 | ... N31: =N27*N30
B33: REVENUE
B34: Average Order Value (£) | C34: =C15 | D34: =C34*(1+$C16) | E34: =D34*(1+$C16) | F34: =E34*(1+$C16) | G34: =F34*(1+$C16) | H34: =G34*(1+$C16) | I34: =H34*(1+$C16) | J34: =I34*(1+$C16) | K34: =J34*(1+$C16) | ... N34: =M34*(1+$C16)
B35: REVENUE (£) | C35: =C31*C34 | D35: =D31*D34 | E35: =E31*E34 | F35: =F31*F34 | G35: =G31*G34 | H35: =H31*H34 | I35: =I31*I34 | J35: =J31*J34 | ... N35: =N31*N34
B37: COSTS
B38: Cost of Goods Sold (£) | C38: =-C35*(1-$C17) | D38: =-D35*(1-$C17) | E38: =-E35*(1-$C17) | F38: =-F35*(1-$C17) | G38: =-G35*(1-$C17) | H38: =-H35*(1-$C17) | I38: =-I35*(1-$C17) | J38: =-J35*(1-$C17) | ... N38: =-N35*(1-$C17)
B39: Distribution Costs (£) | C39: =-C35*$C18 | D39: =-D35*$C18 | E39: =-E35*$C18 | F39: =-F35*$C18 | G39: =-G35*$C18 | H39: =-H35*$C18 | I39: =-I35*$C18 | J39: =-J35*$C18 | ... N39: =-N35*$C18
B40: GROSS PROFIT (£) | C40: =C35+C38+C39 | D40: =D35+D38+D39 | E40: =E35+E38+E39 | F40: =F35+F38+F39 | G40: =G35+G38+G39 | H40: =H35+H38+H39 | I40: =I35+I38+I39 | J40: =J35+J38+J39 | ... N40: =N35+N38+N39
B41: Gross Margin % | C41: =IFERROR(C40/C35,0) | D41: =IFERROR(D40/D35,0) | E41: =IFERROR(E40/E35,0) | F41: =IFERROR(F40/F35,0) | G41: =IFERROR(G40/G35,0) | H41: =IFERROR(H40/H35,0) | I41: =IFERROR(I40/I35,0) | J41: =IFERROR(J40/J35,0) | ... N41: =IFERROR(N40/N35,0)
B43: MARKETING COSTS
B44: Paid Ad Spend (£) | C44: =-C19 | D44: =C44*(1+$C20) | E44: =D44*(1+$C20) | F44: =E44*(1+$C20) | G44: =F44*(1+$C20) | H44: =G44*(1+$C20) | I44: =H44*(1+$C20) | J44: =I44*(1+$C20) | K44: =J44*(1+$C20) | ... N44: =M44*(1+$C20)
B45: SEO & Content (£) | C45: -800 | D45: -800 | E45: -800 | F45: -800 | G45: -800 | H45: -800 | I45: -800 | J45: -800 | K45: -800 | L45: -800 | M45: -800 | N45: -800
B46: Email Marketing (£) | C46: -300 | D46: -300 | E46: -300 | F46: -300 | G46: -300 | H46: -300 | I46: -300 | J46: -300 | K46: -300 | L46: -300 | M46: -300 | N46: -300
B47: TOTAL MARKETING (£) | C47: =C44+C45+C46 | D47: =D44+D45+D46 | E47: =E44+E45+E46 | F47: =F44+F45+F46 | G47: =G44+G45+G46 | H47: =H44+H45+H46 | I47: =I44+I45+I46 | J47: =J44+J45+J46 | ... N47: =N44+N45+N46
B49: OPERATIONAL COSTS
B50: Platform & Hosting (£) | C50: -200 | D50: -200 | E50: -200 | F50: -200 | G50: -200 | H50: -200 | I50: -200 | J50: -200 | K50: -200 | L50: -200 | M50: -200 | N50: -200
...

Sheet GTSEGroup.com
B2: GTSEGroup.com - 12 MONTH PROJECTION
B3: Market: Global B2B | Status: Launch | Currency: GBP (£)
B5: METRIC | C5: M1 | D5: M2 | E5: M3 | F5: M4 | G5: M5 | H5: M6 | I5: M7 | J5: M8 | K5: M9 | L5: M10 | M5: M11 | N5: M12
B7: KEY ASSUMPTIONS (Editable)
B8: Starting Organic Traffic | C8: 200 | D8: visitors
B9: Organic Growth Rate | C9: 0.15 | D9: decimal
B10: Starting Paid Traffic | C10: 800 | D10: visitors
B11: Paid Growth Rate | C11: 0.1 | D11: decimal
B12: Starting Conversion Rate | C12: 0.015 | D12: decimal
B13: Conv. Rate Improvement | C13: 0.0015 | D13: decimal
B14: Max Conversion Rate | C14: 0.03 | D14: decimal
B15: Average Order Value | C15: 250 | D15: currency
B16: AOV Growth Rate | C16: 0.01 | D16: decimal
B17: Gross Margin | C17: 0.45 | D17: decimal
B18: Distribution Cost % | C18: 0.15 | D18: decimal
B19: Starting Ad Spend | C19: 1500 | D19: currency
... B21: Cost Per Click | C21: 1.88 | D21: currency
B23: TRAFFIC
B24: Organic Traffic | C24: =C8 | D24: =C24*(1+$C9) | E24: =D24*(1+$C9) | F24: =E24*(1+$C9) | G24: =F24*(1+$C9) | H24: =G24*(1+$C9) | I24: =H24*(1+$C9) | J24: =I24*(1+$C9) | K24: =J24*(1+$C9) | ... N24: =M24*(1+$C9)
B25: Paid Traffic | C25: =C10 | D25: =C25*(1+$C11) | E25: =D25*(1+$C11) | F25: =E25*(1+$C11) | G25: =F25*(1+$C11) | H25: =G25*(1+$C11) | I25: =H25*(1+$C11) | J25: =I25*(1+$C11) | K25: =J25*(1+$C11) | ... N25: =M25*(1+$C11)
B26: Direct/Referral Traffic | C26: =C24*0.25 | D26: =D24*0.25 | E26: =E24*0.25 | F26: =F24*0.25 | G26: =G24*0.25 | H26: =H24*0.25 | I26: =I24*0.25 | J26: =J24*0.25 | ... N26: =N24*0.25
B27: TOTAL TRAFFIC | C27: =C24+C25+C26 | D27: =D24+D25+D26 | E27: =E24+E25+E26 | F27: =F24+F25+F26 | G27: =G24+G25+G26 | H27: =H24+H25+H26 | I27: =I24+I25+I26 | J27: =J24+J25+J26 | ... N27: =N24+N25+N26
B29: CONVERSION
B30: Conversion Rate | C30: =C12 | D30: =MIN(C30+$C13,$C14) | E30: =MIN(D30+$C13,$C14) | F30: =MIN(E30+$C13,$C14) | G30: =MIN(F30+$C13,$C14) | H30: =MIN(G30+$C13,$C14) | I30: =MIN(H30+$C13,$C14) | J30: =MIN(I30+$C13,$C14) | K30: =MIN(J30+$C13,$C14) | ... N30: =MIN(M30+$C13,$C14)
B31: Orders | C31: =C27*C30 | D31: =D27*D30 | E31: =E27*E30 | F31: =F27*F30 | G31: =G27*G30 | H31: =H27*H30 | I31: =I27*I30 | J31: =J27*J30 | ... N31: =N27*N30
B33: REVENUE
B34: Average Order Value (£) | C34: =C15 | D34: =C34*(1+$C16) | E34: =D34*(1+$C16) | F34: =E34*(1+$C16) | G34: =F34*(1+$C16) | H34: =G34*(1+$C16) | I34: =H34*(1+$C16) | J34: =I34*(1+$C16) | K34: =J34*(1+$C16) | ... N34: =M34*(1+$C16)
B35: REVENUE (£) | C35: =C31*C34 | D35: =D31*D34 | E35: =E31*E34 | F35: =F31*F34 | G35: =G31*G34 | H35: =H31*H34 | I35: =I31*I34 | J35: =J31*J34 | ... N35: =N31*N34
B37: COSTS
B38: Cost of Goods Sold (£) | C38: =-C35*(1-$C17) | D38: =-D35*(1-$C17) | E38: =-E35*(1-$C17) | F38: =-F35*(1-$C17) | G38: =-G35*(1-$C17) | H38: =-H35*(1-$C17) | I38: =-I35*(1-$C17) | J38: =-J35*(1-$C17) | ... N38: =-N35*(1-$C17)
B39: Distribution Costs (£) | C39: =-C35*$C18 | D39: =-D35*$C18 | E39: =-E35*$C18 | F39: =-F35*$C18 | G39: =-G35*$C18 | H39: =-H35*$C18 | I39: =-I35*$C18 | J39: =-J35*$C18 | ... N39: =-N35*$C18
B40: GROSS PROFIT (£) | C40: =C35+C38+C39 | D40: =D35+D38+D39 | E40: =E35+E38+E39 | F40: =F35+F38+F39 | G40: =G35+G38+G39 | H40: =H35+H38+H39 | I40: =I35+I38+I39 | J40: =J35+J38+J39 | ... N40: =N35+N38+N39
B41: Gross Margin % | C41: =IFERROR(C40/C35,0) | D41: =IFERROR(D40/D35,0) | E41: =IFERROR(E40/E35,0) | F41: =IFERROR(F40/F35,0) | G41: =IFERROR(G40/G35,0) | H41: =IFERROR(H40/H35,0) | I41: =IFERROR(I40/I35,0) | J41: =IFERROR(J40/J35,0) | ... N41: =IFERROR(N40/N35,0)
B43: MARKETING COSTS
B44: Paid Ad Spend (£) | C44: =-C19 | D44: =C44*(1+$C20) | E44: =D44*(1+$C20) | F44: =E44*(1+$C20) | G44: =F44*(1+$C20) | H44: =G44*(1+$C20) | I44: =H44*(1+$C20) | J44: =I44*(1+$C20) | K44: =J44*(1+$C20) | ... N44: =M44*(1+$C20)
B45: SEO & Content (£) | C45: -1200 | D45: -1200 | E45: -1200 | F45: -1200 | G45: -1200 | H45: -1200 | I45: -1200 | J45: -1200 | K45: -1200 | L45: -1200 | M45: -1200 | N45: -1200
B46: Email Marketing (£) | C46: -200 | D46: -200 | E46: -200 | F46: -200 | G46: -200 | H46: -200 | I46: -200 | J46: -200 | K46: -200 | L46: -200 | M46: -200 | N46: -200
B47: TOTAL MARKETING (£) | C47: =C44+C45+C46 | D47: =D44+D45+D46 | E47: =E44+E45+E46 | F47: =F44+F45+F46 | G47: =G44+G45+G46 | H47: =H44+H45+H46 | I47: =I44+I45+I46 | J47: =J44+J45+J46 | ... N47: =N44+N45+N46
B49: OPERATIONAL COSTS
B50: Platform & Hosting (£) | C50: -150 | D50: -150 | E50: -150 | F50: -150 | G50: -150 | H50: -150 | I50: -150 | J50: -150 | K50: -150 | L50: -150 | M50: -150 | N50: -150
...

Sheet SSH UK
B2: SafetySignHub UK - 12 MONTH PROJECTION
B3: Market: UK B2C | Status: Growth | Currency: GBP (£)
B5: METRIC | C5: M1 | D5: M2 | E5: M3 | F5: M4 | G5: M5 | H5: M6 | I5: M7 | J5: M8 | K5: M9 | L5: M10 | M5: M11 | N5: M12
B7: KEY ASSUMPTIONS (Editable)
B8: Starting Organic Traffic | C8: 500 | D8: visitors
B9: Organic Growth Rate | C9: 0.08 | D9: decimal
B10: Starting Paid Traffic | C10: 1000 | D10: visitors
B11: Paid Growth Rate | C11: 0.08 | D11: decimal
B12: Starting Conversion Rate | C12: 0.022 | D12: decimal
B13: Conv. Rate Improvement | C13: 0.001 | D13: decimal
B14: Max Conversion Rate | C14: 0.038 | D14: decimal
B15: Average Order Value | C15: 75 | D15: currency
B16: AOV Growth Rate | C16: 0.005 | D16: decimal
B17: Gross Margin | C17: 0.38 | D17: decimal
B18: Distribution Cost % | C18: 0.22 | D18: decimal
B19: Starting Ad Spend | C19: 2000 | D19: currency
... B21: Cost Per Click | C21: 2 | D21: currency
B23: TRAFFIC
B24: Organic Traffic | C24: =C8 | D24: =C24*(1+$C9) | E24: =D24*(1+$C9) | F24: =E24*(1+$C9) | G24: =F24*(1+$C9) | H24: =G24*(1+$C9) | I24: =H24*(1+$C9) | J24: =I24*(1+$C9) | K24: =J24*(1+$C9) | ... N24: =M24*(1+$C9)
B25: Paid Traffic | C25: =C10 | D25: =C25*(1+$C11) | E25: =D25*(1+$C11) | F25: =E25*(1+$C11) | G25: =F25*(1+$C11) | H25: =G25*(1+$C11) | I25: =H25*(1+$C11) | J25: =I25*(1+$C11) | K25: =J25*(1+$C11) | ... N25: =M25*(1+$C11)
B26: Direct/Referral Traffic | C26: =C24*0.25 | D26: =D24*0.25 | E26: =E24*0.25 | F26: =F24*0.25 | G26: =G24*0.25 | H26: =H24*0.25 | I26: =I24*0.25 | J26: =J24*0.25 | ... N26: =N24*0.25
B27: TOTAL TRAFFIC | C27: =C24+C25+C26 | D27: =D24+D25+D26 | E27: =E24+E25+E26 | F27: =F24+F25+F26 | G27: =G24+G25+G26 | H27: =H24+H25+H26 | I27: =I24+I25+I26 | J27: =J24+J25+J26 | ... N27: =N24+N25+N26
B29: CONVERSION
B30: Conversion Rate | C30: =C12 | D30: =MIN(C30+$C13,$C14) | E30: =MIN(D30+$C13,$C14) | F30: =MIN(E30+$C13,$C14) | G30: =MIN(F30+$C13,$C14) | H30: =MIN(G30+$C13,$C14) | I30: =MIN(H30+$C13,$C14) | J30: =MIN(I30+$C13,$C14) | K30: =MIN(J30+$C13,$C14) | ... N30: =MIN(M30+$C13,$C14)
B31: Orders | C31: =C27*C30 | D31: =D27*D30 | E31: =E27*E30 | F31: =F27*F30 | G31: =G27*G30 | H31: =H27*H30 | I31: =I27*I30 | J31: =J27*J30 | ... N31: =N27*N30
B33: REVENUE
B34: Average Order Value (£) | C34: =C15 | D34: =C34*(1+$C16) | E34: =D34*(1+$C16) | F34: =E34*(1+$C16) | G34: =F34*(1+$C16) | H34: =G34*(1+$C16) | I34: =H34*(1+$C16) | J34: =I34*(1+$C16) | K34: =J34*(1+$C16) | ... N34: =M34*(1+$C16)
B35: REVENUE (£) | C35: =C31*C34 | D35: =D31*D34 | E35: =E31*E34 | F35: =F31*F34 | G35: =G31*G34 | H35: =H31*H34 | I35: =I31*I34 | J35: =J31*J34 | ... N35: =N31*N34
B37: COSTS
B38: Cost of Goods Sold (£) | C38: =-C35*(1-$C17) | D38: =-D35*(1-$C17) | E38: =-E35*(1-$C17) | F38: =-F35*(1-$C17) | G38: =-G35*(1-$C17) | H38: =-H35*(1-$C17) | I38: =-I35*(1-$C17) | J38: =-J35*(1-$C17) | ... N38: =-N35*(1-$C17)
B39: Distribution Costs (£) | C39: =-C35*$C18 | D39: =-D35*$C18 | E39: =-E35*$C18 | F39: =-F35*$C18 | G39: =-G35*$C18 | H39: =-H35*$C18 | I39: =-I35*$C18 | J39: =-J35*$C18 | ... N39: =-N35*$C18
B40: GROSS PROFIT (£) | C40: =C35+C38+C39 | D40: =D35+D38+D39 | E40: =E35+E38+E39 | F40: =F35+F38+F39 | G40: =G35+G38+G39 | H40: =H35+H38+H39 | I40: =I35+I38+I39 | J40: =J35+J38+J39 | ... N40: =N35+N38+N39
B41: Gross Margin % | C41: =IFERROR(C40/C35,0) | D41: =IFERROR(D40/D35,0) | E41: =IFERROR(E40/E35,0) | F41: =IFERROR(F40/F35,0) | G41: =IFERROR(G40/G35,0) | H41: =IFERROR(H40/H35,0) | I41: =IFERROR(I40/I35,0) | J41: =IFERROR(J40/J35,0) | ... N41: =IFERROR(N40/N35,0)
B43: MARKETING COSTS
B44: Paid Ad Spend (£) | C44: =-C19 | D44: =C44*(1+$C20) | E44: =D44*(1+$C20) | F44: =E44*(1+$C20) | G44: =F44*(1+$C20) | H44: =G44*(1+$C20) | I44: =H44*(1+$C20) | J44: =I44*(1+$C20) | K44: =J44*(1+$C20) | ... N44: =M44*(1+$C20)
B45: SEO & Content (£) | C45: -1000 | D45: -1000 | E45: -1000 | F45: -1000 | G45: -1000 | H45: -1000 | I45: -1000 | J45: -1000 | K45: -1000 | L45: -1000 | M45: -1000 | N45: -1000
B46: Email Marketing (£) | C46: -400 | D46: -400 | E46: -400 | F46: -400 | G46: -400 | H46: -400 | I46: -400 | J46: -400 | K46: -400 | L46: -400 | M46: -400 | N46: -400
B47: TOTAL MARKETING (£) | C47: =C44+C45+C46 | D47: =D44+D45+D46 | E47: =E44+E45+E46 | F47: =F44+F45+F46 | G47: =G44+G45+G46 | H47: =H44+H45+H46 | I47: =I44+I45+I46 | J47: =J44+J45+J46 | ... N47: =N44+N45+N46
B49: OPERATIONAL COSTS
B50: Platform & Hosting (£) | C50: -180 | D50: -180 | E50: -180 | F50: -180 | G50: -180 | H50: -180 | I50: -180 | J50: -180 | K50: -180 | L50: -180 | M50: -180 | N50: -180
...

Sheet SSH USA
B2: SafetySignHub USA - 12 MONTH PROJECTION
B3: Market: USA B2C | Status: Launch | Currency: GBP (£)
B5: METRIC | C5: M1 | D5: M2 | E5: M3 | F5: M4 | G5: M5 | H5: M6 | I5: M7 | J5: M8 | K5: M9 | L5: M10 | M5: M11 | N5: M12
B7: KEY ASSUMPTIONS (Editable)
B8: Starting Organic Traffic | C8: 300 | D8: visitors
B9: Organic Growth Rate | C9: 0.15 | D9: decimal
B10: Starting Paid Traffic | C10: 1500 | D10: visitors
B11: Paid Growth Rate | C11: 0.12 | D11: decimal
B12: Starting Conversion Rate | C12: 0.02 | D12: decimal
B13: Conv. Rate Improvement | C13: 0.0012 | D13: decimal
B14: Max Conversion Rate | C14: 0.035 | D14: decimal
B15: Average Order Value | C15: 90 | D15: currency
B16: AOV Growth Rate | C16: 0.01 | D16: decimal
B17: Gross Margin | C17: 0.4 | D17: decimal
B18: Distribution Cost % | C18: 0.2 | D18: decimal
B19: Starting Ad Spend | C19: 3000 | D19: currency
... B21: Cost Per Click | C21: 2 | D21: currency
B23: TRAFFIC
B24: Organic Traffic | C24: =C8 | D24: =C24*(1+$C9) | E24: =D24*(1+$C9) | F24: =E24*(1+$C9) | G24: =F24*(1+$C9) | H24: =G24*(1+$C9) | I24: =H24*(1+$C9) | J24: =I24*(1+$C9) | K24: =J24*(1+$C9) | ... N24: =M24*(1+$C9)
B25: Paid Traffic | C25: =C10 | D25: =C25*(1+$C11) | E25: =D25*(1+$C11) | F25: =E25*(1+$C11) | G25: =F25*(1+$C11) | H25: =G25*(1+$C11) | I25: =H25*(1+$C11) | J25: =I25*(1+$C11) | K25: =J25*(1+$C11) | ... N25: =M25*(1+$C11)
B26: Direct/Referral Traffic | C26: =C24*0.25 | D26: =D24*0.25 | E26: =E24*0.25 | F26: =F24*0.25 | G26: =G24*0.25 | H26: =H24*0.25 | I26: =I24*0.25 | J26: =J24*0.25 | ... N26: =N24*0.25
B27: TOTAL TRAFFIC | C27: =C24+C25+C26 | D27: =D24+D25+D26 | E27: =E24+E25+E26 | F27: =F24+F25+F26 | G27: =G24+G25+G26 | H27: =H24+H25+H26 | I27: =I24+I25+I26 | J27: =J24+J25+J26 | ... N27: =N24+N25+N26
B29: CONVERSION
B30: Conversion Rate | C30: =C12 | D30: =MIN(C30+$C13,$C14) | E30: =MIN(D30+$C13,$C14) | F30: =MIN(E30+$C13,$C14) | G30: =MIN(F30+$C13,$C14) | H30: =MIN(G30+$C13,$C14) | I30: =MIN(H30+$C13,$C14) | J30: =MIN(I30+$C13,$C14) | K30: =MIN(J30+$C13,$C14) | ... N30: =MIN(M30+$C13,$C14)
B31: Orders | C31: =C27*C30 | D31: =D27*D30 | E31: =E27*E30 | F31: =F27*F30 | G31: =G27*G30 | H31: =H27*H30 | I31: =I27*I30 | J31: =J27*J30 | ... N31: =N27*N30
B33: REVENUE
B34: Average Order Value (£) | C34: =C15 | D34: =C34*(1+$C16) | E34: =D34*(1+$C16) | F34: =E34*(1+$C16) | G34: =F34*(1+$C16) | H34: =G34*(1+$C16) | I34: =H34*(1+$C16) | J34: =I34*(1+$C16) | K34: =J34*(1+$C16) | ... N34: =M34*(1+$C16)
B35: REVENUE (£) | C35: =C31*C34 | D35: =D31*D34 | E35: =E31*E34 | F35: =F31*F34 | G35: =G31*G34 | H35: =H31*H34 | I35: =I31*I34 | J35: =J31*J34 | ... N35: =N31*N34
B37: COSTS
B38: Cost of Goods Sold (£) | C38: =-C35*(1-$C17) | D38: =-D35*(1-$C17) | E38: =-E35*(1-$C17) | F38: =-F35*(1-$C17) | G38: =-G35*(1-$C17) | H38: =-H35*(1-$C17) | I38: =-I35*(1-$C17) | J38: =-J35*(1-$C17) | ... N38: =-N35*(1-$C17)
B39: Distribution Costs (£) | C39: =-C35*$C18 | D39: =-D35*$C18 | E39: =-E35*$C18 | F39: =-F35*$C18 | G39: =-G35*$C18 | H39: =-H35*$C18 | I39: =-I35*$C18 | J39: =-J35*$C18 | ... N39: =-N35*$C18
B40: GROSS PROFIT (£) | C40: =C35+C38+C39 | D40: =D35+D38+D39 | E40: =E35+E38+E39 | F40: =F35+F38+F39 | G40: =G35+G38+G39 | H40: =H35+H38+H39 | I40: =I35+I38+I39 | J40: =J35+J38+J39 | ... N40: =N35+N38+N39
B41: Gross Margin % | C41: =IFERROR(C40/C35,0) | D41: =IFERROR(D40/D35,0) | E41: =IFERROR(E40/E35,0) | F41: =IFERROR(F40/F35,0) | G41: =IFERROR(G40/G35,0) | H41: =IFERROR(H40/H35,0) | I41: =IFERROR(I40/I35,0) | J41: =IFERROR(J40/J35,0) | ... N41: =IFERROR(N40/N35,0)
B43: MARKETING COSTS
B44: Paid Ad Spend (£) | C44: =-C19 | D44: =C44*(1+$C20) | E44: =D44*(1+$C20) | F44: =E44*(1+$C20) | G44: =F44*(1+$C20) | H44: =G44*(1+$C20) | I44: =H44*(1+$C20) | J44: =I44*(1+$C20) | K44: =J44*(1+$C20) | ... N44: =M44*(1+$C20)
B45: SEO & Content (£) | C45: -1500 | D45: -1500 | E45: -1500 | F45: -1500 | G45: -1500 | H45: -1500 | I45: -1500 | J45: -1500 | K45: -1500 | L45: -1500 | M45: -1500 | N45: -1500
B46: Email Marketing (£) | C46: -500 | D46: -500 | E46: -500 | F46: -500 | G46: -500 | H46: -500 | I46: -500 | J46: -500 | K46: -500 | L46: -500 | M46: -500 | N46: -500
B47: TOTAL MARKETING (£) | C47: =C44+C45+C46 | D47: =D44+D45+D46 | E47: =E44+E45+E46 | F47: =F44+F45+F46 | G47: =G44+G45+G46 | H47: =H44+H45+H46 | I47: =I44+I45+I46 | J47: =J44+J45+J46 | ... N47: =N44+N45+N46
B49: OPERATIONAL COSTS
B50: Platform & Hosting (£) | C50: -180 | D50: -180 | E50: -180 | F50: -180 | G50: -180 | H50: -180 | I50: -180 | J50: -180 | K50: -180 | L50: -180 | M50: -180 | N50: -180
...

Sheet Epha.com
B2: Epha.com - 12 MONTH PROJECTION
B3: Market: Global Premium | Status: Beta | Currency: GBP (£)
B5: METRIC | C5: M1 | D5: M2 | E5: M3 | F5: M4 | G5: M5 | H5: M6 | I5: M7 | J5: M8 | K5: M9 | L5: M10 | M5: M11 | N5: M12
B7: KEY ASSUMPTIONS (Editable)
B8: Starting Organic Traffic | C8: 150 | D8: visitors
B9: Organic Growth Rate | C9: 0.2 | D9: decimal
B10: Starting Paid Traffic | C10: 600 | D10: visitors
B11: Paid Growth Rate | C11: 0.1 | D11: decimal
B12: Starting Conversion Rate | C12: 0.018 | D12: decimal
B13: Conv. Rate Improvement | C13: 0.0015 | D13: decimal
B14: Max Conversion Rate | C14: 0.032 | D14: decimal
B15: Average Order Value | C15: 120 | D15: currency
B16: AOV Growth Rate | C16: 0.01 | D16: decimal
B17: Gross Margin | C17: 0.5 | D17: decimal
B18: Distribution Cost % | C18: 0.18 | D18: decimal
B19: Starting Ad Spend | C19: 1200 | D19: currency
... B21: Cost Per Click | C21: 2 | D21: currency
B23: TRAFFIC
B24: Organic Traffic | C24: =C8 | D24: =C24*(1+$C9) | E24: =D24*(1+$C9) | F24: =E24*(1+$C9) | G24: =F24*(1+$C9) | H24: =G24*(1+$C9) | I24: =H24*(1+$C9) | J24: =I24*(1+$C9) | K24: =J24*(1+$C9) | ... N24: =M24*(1+$C9)
B25: Paid Traffic | C25: =C10 | D25: =C25*(1+$C11) | E25: =D25*(1+$C11) | F25: =E25*(1+$C11) | G25: =F25*(1+$C11) | H25: =G25*(1+$C11) | I25: =H25*(1+$C11) | J25: =I25*(1+$C11) | K25: =J25*(1+$C11) | ... N25: =M25*(1+$C11)
B26: Direct/Referral Traffic | C26: =C24*0.25 | D26: =D24*0.25 | E26: =E24*0.25 | F26: =F24*0.25 | G26: =G24*0.25 | H26: =H24*0.25 | I26: =I24*0.25 | J26: =J24*0.25 | ... N26: =N24*0.25
B27: TOTAL TRAFFIC | C27: =C24+C25+C26 | D27: =D24+D25+D26 | E27: =E24+E25+E26 | F27: =F24+F25+F26 | G27: =G24+G25+G26 | H27: =H24+H25+H26 | I27: =I24+I25+I26 | J27: =J24+J25+J26 | ... N27: =N24+N25+N26
B29: CONVERSION
B30: Conversion Rate | C30: =C12 | D30: =MIN(C30+$C13,$C14) | E30: =MIN(D30+$C13,$C14) | F30: =MIN(E30+$C13,$C14) | G30: =MIN(F30+$C13,$C14) | H30: =MIN(G30+$C13,$C14) | I30: =MIN(H30+$C13,$C14) | J30: =MIN(I30+$C13,$C14) | K30: =MIN(J30+$C13,$C14) | ... N30: =MIN(M30+$C13,$C14)
B31: Orders | C31: =C27*C30 | D31: =D27*D30 | E31: =E27*E30 | F31: =F27*F30 | G31: =G27*G30 | H31: =H27*H30 | I31: =I27*I30 | J31: =J27*J30 | ... N31: =N27*N30
B33: REVENUE
B34: Average Order Value (£) | C34: =C15 | D34: =C34*(1+$C16) | E34: =D34*(1+$C16) | F34: =E34*(1+$C16) | G34: =F34*(1+$C16) | H34: =G34*(1+$C16) | I34: =H34*(1+$C16) | J34: =I34*(1+$C16) | K34: =J34*(1+$C16) | ... N34: =M34*(1+$C16)
B35: REVENUE (£) | C35: =C31*C34 | D35: =D31*D34 | E35: =E31*E34 | F35: =F31*F34 | G35: =G31*G34 | H35: =H31*H34 | I35: =I31*I34 | J35: =J31*J34 | ... N35: =N31*N34
B37: COSTS
B38: Cost of Goods Sold (£) | C38: =-C35*(1-$C17) | D38: =-D35*(1-$C17) | E38: =-E35*(1-$C17) | F38: =-F35*(1-$C17) | G38: =-G35*(1-$C17) | H38: =-H35*(1-$C17) | I38: =-I35*(1-$C17) | J38: =-J35*(1-$C17) | ... N38: =-N35*(1-$C17)
B39: Distribution Costs (£) | C39: =-C35*$C18 | D39: =-D35*$C18 | E39: =-E35*$C18 | F39: =-F35*$C18 | G39: =-G35*$C18 | H39: =-H35*$C18 | I39: =-I35*$C18 | J39: =-J35*$C18 | ... N39: =-N35*$C18
B40: GROSS PROFIT (£) | C40: =C35+C38+C39 | D40: =D35+D38+D39 | E40: =E35+E38+E39 | F40: =F35+F38+F39 | G40: =G35+G38+G39 | H40: =H35+H38+H39 | I40: =I35+I38+I39 | J40: =J35+J38+J39 | ... N40: =N35+N38+N39
B41: Gross Margin % | C41: =IFERROR(C40/C35,0) | D41: =IFERROR(D40/D35,0) | E41: =IFERROR(E40/E35,0) | F41: =IFERROR(F40/F35,0) | G41: =IFERROR(G40/G35,0) | H41: =IFERROR(H40/H35,0) | I41: =IFERROR(I40/I35,0) | J41: =IFERROR(J40/J35,0) | ... N41: =IFERROR(N40/N35,0)
B43: MARKETING COSTS
B44: Paid Ad Spend (£) | C44: =-C19 | D44: =C44*(1+$C20) | E44: =D44*(1+$C20) | F44: =E44*(1+$C20) | G44: =F44*(1+$C20) | H44: =G44*(1+$C20) | I44: =H44*(1+$C20) | J44: =I44*(1+$C20) | K44: =J44*(1+$C20) | ... N44: =M44*(1+$C20)
B45: SEO & Content (£) | C45: -1000 | D45: -1000 | E45: -1000 | F45: -1000 | G45: -1000 | H45: -1000 | I45: -1000 | J45: -1000 | K45: -1000 | L45: -1000 | M45: -1000 | N45: -1000
B46: Email Marketing (£) | C46: -300 | D46: -300 | E46: -300 | F46: -300 | G46: -300 | H46: -300 | I46: -300 | J46: -300 | K46: -300 | L46: -300 | M46: -300 | N46: -300
B47: TOTAL MARKETING (£) | C47: =C44+C45+C46 | D47: =D44+D45+D46 | E47: =E44+E45+E46 | F47: =F44+F45+F46 | G47: =G44+G45+G46 | H47: =H44+H45+H46 | I47: =I44+I45+I46 | J47: =J44+J45+J46 | ... N47: =N44+N45+N46
B49: OPERATIONAL COSTS
B50: Platform & Hosting (£) | C50: -250 | D50: -250 | E50: -250 | F50: -250 | G50: -250 | H50: -250 | I50: -250 | J50: -250 | K50: -250 | L50: -250 | M50: -250 | N50: -250
...

Sheet Consolidated
B2: PORTFOLIO CONSOLIDATED VIEW
B3: Aggregated 12-Month Projection for All 5 Sites | Currency: GBP (£)
B5: METRIC | C5: M1 | D5: M2 | E5: M3 | F5: M4 | G5: M5 | H5: M6 | I5: M7 | J5: M8 | K5: M9 | L5: M10 | M5: M11 | N5: M12
B7: SITE SUMMARY
B8: GTSE.co.uk Revenue (£) | C8: ='GTSE.co.uk'!C35 | D8: ='GTSE.co.uk'!D35 | E8: ='GTSE.co.uk'!E35 | F8: ='GTSE.co.uk'!F35 | G8: ='GTSE.co.uk'!G35 | H8: ='GTSE.co.uk'!H35 | I8: ='GTSE.co.uk'!I35 | J8: ='GTSE.co.uk'!J35 | ... N8: ='GTSE.co.uk'!N35
B9: GTSEGroup.com Revenue (£) | C9: ='GTSEGroup.com'!C35 | D9: ='GTSEGroup.com'!D35 | E9: ='GTSEGroup.com'!E35 | F9: ='GTSEGroup.com'!F35 | G9: ='GTSEGroup.com'!G35 | H9: ='GTSEGroup.com'!H35 | I9: ='GTSEGroup.com'!I35 | J9: ='GTSEGroup.com'!J35 | ... N9: ='GTSEGroup.com'!N35
B10: SSH UK Revenue (£) | C10: ='SSH UK'!C35 | D10: ='SSH UK'!D35 | E10: ='SSH UK'!E35 | F10: ='SSH UK'!F35 | G10: ='SSH UK'!G35 | H10: ='SSH UK'!H35 | I10: ='SSH UK'!I35 | J10: ='SSH UK'!J35 | ... N10: ='SSH UK'!N35
B11: SSH USA Revenue (£) | C11: ='SSH USA'!C35 | D11: ='SSH USA'!D35 | E11: ='SSH USA'!E35 | F11: ='SSH USA'!F35 | G11: ='SSH USA'!G35 | H11: ='SSH USA'!H35 | I11: ='SSH USA'!I35 | J11: ='SSH USA'!J35 | ... N11: ='SSH USA'!N35
B12: Epha.com Revenue (£) | C12: ='Epha.com'!C35 | D12: ='Epha.com'!D35 | E12: ='Epha.com'!E35 | F12: ='Epha.com'!F35 | G12: ='Epha.com'!G35 | H12: ='Epha.com'!H35 | I12: ='Epha.com'!I35 | J12: ='Epha.com'!J35 | ... N12: ='Epha.com'!N35
B13: TOTAL REVENUE (£) | C13: ='GTSE.co.uk'!C35+'GTSEGroup.com'!C35+'SSH UK'!C35+'SSH USA'!C35+'Epha.com'!C35 | D13: ='GTSE.co.uk'!D35+'GTSEGroup.com'!D35+'SSH UK'!D35+'SSH USA'!D35+'Epha.com'!D35 | E13: ='GTSE.co.uk'!E35+'GTSEGroup.com'!E35+'SSH UK'!E35+'SSH USA'!E35+'Epha.com'!E35 | F13: ='GTSE.co.uk'!F35+'GTSEGroup.com'!F35+'SSH UK'!F35+'SSH USA'!F35+'Epha.com'!F35 | G13: ='GTSE.co.uk'!G35+'GTSEGroup.com'!G35+'SSH UK'!G35+'SSH USA'!G35+'Epha.com'!G35 | H13: ='GTSE.co.uk'!H35+'GTSEGroup.com'!H35+'SSH UK'!H35+'SSH USA'!H35+'Epha.com'!H35 | I13: ='GTSE.co.uk'!I35+'GTSEGroup.com'!I35+'SSH UK'!I35+'SSH USA'!I35+'Epha.com'!I35 | J13: ='GTSE.co.uk'!J35+'GTSEGroup.com'!J35+'SSH UK'!J35+'SSH USA'!J35+'Epha.com'!J35 | ... N13: ='GTSE.co.uk'!N35+'GTSEGroup.com'!N35+'SSH UK'!N35+'SSH USA'!N35+'Epha.com'!N35
B15: TRAFFIC (All Sites)
B16: Total Traffic (All Sites) | C16: ='GTSE.co.uk'!C27+'GTSEGroup.com'!C27+'SSH UK'!C27+'SSH USA'!C27+'Epha.com'!C27 | D16: ='GTSE.co.uk'!D27+'GTSEGroup.com'!D27+'SSH UK'!D27+'SSH USA'!D27+'Epha.com'!D27 | E16: ='GTSE.co.uk'!E27+'GTSEGroup.com'!E27+'SSH UK'!E27+'SSH USA'!E27+'Epha.com'!E27 | F16: ='GTSE.co.uk'!F27+'GTSEGroup.com'!F27+'SSH UK'!F27+'SSH USA'!F27+'Epha.com'!F27 | G16: ='GTSE.co.uk'!G27+'GTSEGroup.com'!G27+'SSH UK'!G27+'SSH USA'!G27+'Epha.com'!G27 | H16: ='GTSE.co.uk'!H27+'GTSEGroup.com'!H27+'SSH UK'!H27+'SSH USA'!H27+'Epha.com'!H27 | I16: ='GTSE.co.uk'!I27+'GTSEGroup.com'!I27+'SSH UK'!I27+'SSH USA'!I27+'Epha.com'!I27 | J16: ='GTSE.co.uk'!J27+'GTSEGroup.com'!J27+'SSH UK'!J27+'SSH USA'!J27+'Epha.com'!J27 | ... N16: ='GTSE.co.uk'!N27+'GTSEGroup.com'!N27+'SSH UK'!N27+'SSH USA'!N27+'Epha.com'!N27
B17: Total Orders (All Sites) | C17: ='GTSE.co.uk'!C31+'GTSEGroup.com'!C31+'SSH UK'!C31+'SSH USA'!C31+'Epha.com'!C31 | D17: ='GTSE.co.uk'!D31+'GTSEGroup.com'!D31+'SSH UK'!D31+'SSH USA'!D31+'Epha.com'!D31 | E17: ='GTSE.co.uk'!E31+'GTSEGroup.com'!E31+'SSH UK'!E31+'SSH USA'!E31+'Epha.com'!E31 | F17: ='GTSE.co.uk'!F31+'GTSEGroup.com'!F31+'SSH UK'!F31+'SSH USA'!F31+'Epha.com'!F31 | G17: ='GTSE.co.uk'!G31+'GTSEGroup.com'!G31+'SSH UK'!G31+'SSH USA'!G31+'Epha.com'!G31 | H17: ='GTSE.co.uk'!H31+'GTSEGroup.com'!H31+'SSH UK'!H31+'SSH USA'!H31+'Epha.com'!H31 | I17: ='GTSE.co.uk'!I31+'GTSEGroup.com'!I31+'SSH UK'!I31+'SSH USA'!I31+'Epha.com'!I31 | J17: ='GTSE.co.uk'!J31+'GTSEGroup.com'!J31+'SSH UK'!J31+'SSH USA'!J31+'Epha.com'!J31 | ... N17: ='GTSE.co.uk'!N31+'GTSEGroup.com'!N31+'SSH UK'!N31+'SSH USA'!N31+'Epha.com'!N31
B18: Portfolio Conversion Rate | C18: =IFERROR(C17/C16,0) | D18: =IFERROR(D17/D16,0) | E18: =IFERROR(E17/E16,0) | F18: =IFERROR(F17/F16,0) | G18: =IFERROR(G17/G16,0) | H18: =IFERROR(H17/H16,0) | I18: =IFERROR(I17/I16,0) | J18: =IFERROR(J17/J16,0) | ... N18: =IFERROR(N17/N16,0)
B20: COSTS (All Sites)
B21: Gross Profit (£) | C21: ='GTSE.co.uk'!C40+'GTSEGroup.com'!C40+'SSH UK'!C40+'SSH USA'!C40+'Epha.com'!C40 | D21: ='GTSE.co.uk'!D40+'GTSEGroup.com'!D40+'SSH UK'!D40+'SSH USA'!D40+'Epha.com'!D40 | E21: ='GTSE.co.uk'!E40+'GTSEGroup.com'!E40+'SSH UK'!E40+'SSH USA'!E40+'Epha.com'!E40 | F21: ='GTSE.co.uk'!F40+'GTSEGroup.com'!F40+'SSH UK'!F40+'SSH USA'!F40+'Epha.com'!F40 | G21: ='GTSE.co.uk'!G40+'GTSEGroup.com'!G40+'SSH UK'!G40+'SSH USA'!G40+'Epha.com'!G40 | H21: ='GTSE.co.uk'!H40+'GTSEGroup.com'!H40+'SSH UK'!H40+'SSH USA'!H40+'Epha.com'!H40 | I21: ='GTSE.co.uk'!I40+'GTSEGroup.com'!I40+'SSH UK'!I40+'SSH USA'!I40+'Epha.com'!I40 | J21: ='GTSE.co.uk'!J40+'GTSEGroup.com'!J40+'SSH UK'!J40+'SSH USA'!J40+'Epha.com'!J40 | ... N21: ='GTSE.co.uk'!N40+'GTSEGroup.com'!N40+'SSH UK'!N40+'SSH USA'!N40+'Epha.com'!N40
B22: Total Marketing (£) | C22: ='GTSE.co.uk'!C47+'GTSEGroup.com'!C47+'SSH UK'!C47+'SSH USA'!C47+'Epha.com'!C47 | D22: ='GTSE.co.uk'!D47+'GTSEGroup.com'!D47+'SSH UK'!D47+'SSH USA'!D47+'Epha.com'!D47 | E22: ='GTSE.co.uk'!E47+'GTSEGroup.com'!E47+'SSH UK'!E47+'SSH USA'!E47+'Epha.com'!E47 | F22: ='GTSE.co.uk'!F47+'GTSEGroup.com'!F47+'SSH UK'!F47+'SSH USA'!F47+'Epha.com'!F47 | G22: ='GTSE.co.uk'!G47+'GTSEGroup.com'!G47+'SSH UK'!G47+'SSH USA'!G47+'Epha.com'!G47 | H22: ='GTSE.co.uk'!H47+'GTSEGroup.com'!H47+'SSH UK'!H47+'SSH USA'!H47+'Epha.com'!H47 | I22: ='GTSE.co.uk'!I47+'GTSEGroup.com'!I47+'SSH UK'!I47+'SSH USA'!I47+'Epha.com'!I47 | J22: ='GTSE.co.uk'!J47+'GTSEGroup.com'!J47+'SSH UK'!J47+'SSH USA'!J47+'Epha.com'!J47 | ... N22: ='GTSE.co.uk'!N47+'GTSEGroup.com'!N47+'SSH UK'!N47+'SSH USA'!N47+'Epha.com'!N47
B23: Total Operational (£) | C23: ='GTSE.co.uk'!C54+'GTSEGroup.com'!C54+'SSH UK'!C54+'SSH USA'!C54+'Epha.com'!C54 | D23: ='GTSE.co.uk'!D54+'GTSEGroup.com'!D54+'SSH UK'!D54+'SSH USA'!D54+'Epha.com'!D54 | E23: ='GTSE.co.uk'!E54+'GTSEGroup.com'!E54+'SSH UK'!E54+'SSH USA'!E54+'Epha.com'!E54 | F23: ='GTSE.co.uk'!F54+'GTSEGroup.com'!F54+'SSH UK'!F54+'SSH USA'!F54+'Epha.com'!F54 | G23: ='GTSE.co.uk'!G54+'GTSEGroup.com'!G54+'SSH UK'!G54+'SSH USA'!G54+'Epha.com'!G54 | H23: ='GTSE.co.uk'!H54+'GTSEGroup.com'!H54+'SSH UK'!H54+'SSH USA'!H54+'Epha.com'!H54 | I23: ='GTSE.co.uk'!I54+'GTSEGroup.com'!I54+'SSH UK'!I54+'SSH USA'!I54+'Epha.com'!I54 | J23: ='GTSE.co.uk'!J54+'GTSEGroup.com'!J54+'SSH UK'!J54+'SSH USA'!J54+'Epha.com'!J54 | ... N23: ='GTSE.co.uk'!N54+'GTSEGroup.com'!N54+'SSH UK'!N54+'SSH USA'!N54+'Epha.com'!N54
B25: PROFITABILITY
B26: TOTAL CONTRIBUTION (£) | C26: ='GTSE.co.uk'!C57+'GTSEGroup.com'!C57+'SSH UK'!C57+'SSH USA'!C57+'Epha.com'!C57 | D26: ='GTSE.co.uk'!D57+'GTSEGroup.com'!D57+'SSH UK'!D57+'SSH USA'!D57+'Epha.com'!D57 | E26: ='GTSE.co.uk'!E57+'GTSEGroup.com'!E57+'SSH UK'!E57+'SSH USA'!E57+'Epha.com'!E57 | F26: ='GTSE.co.uk'!F57+'GTSEGroup.com'!F57+'SSH UK'!F57+'SSH USA'!F57+'Epha.com'!F57 | G26: ='GTSE.co.uk'!G57+'GTSEGroup.com'!G57+'SSH UK'!G57+'SSH USA'!G57+'Epha.com'!G57 | H26: ='GTSE.co.uk'!H57+'GTSEGroup.com'!H57+'SSH UK'!H57+'SSH USA'!H57+'Epha.com'!H57 | I26: ='GTSE.co.uk'!I57+'GTSEGroup.com'!I57+'SSH UK'!I57+'SSH USA'!I57+'Epha.com'!I57 | J26: ='GTSE.co.uk'!J57+'GTSEGroup.com'!J57+'SSH UK'!J57+'SSH USA'!J57+'Epha.com'!J57 | ... N26: ='GTSE.co.uk'!N57+'GTSEGroup.com'!N57+'SSH UK'!N57+'SSH USA'!N57+'Epha.com'!N57
B27: Cumulative Contribution (£) | C27: =C26 | D27: =C27+D26 | E27: =D27+E26 | F27: =E27+F26 | G27: =F27+G26 | H27: =G27+H26 | I27: =H27+I26 | J27: =I27+J26 | K27: =J27+K26 | ... N27: =M27+N26
B29: PORTFOLIO KPIs
B30: Portfolio ROAS | C30: =IFERROR(C13/ABS(C22),0) | D30: =IFERROR(D13/ABS(D22),0) | E30: =IFERROR(E13/ABS(E22),0) | F30: =IFERROR(F13/ABS(F22),0) | G30: =IFERROR(G13/ABS(G22),0) | H30: =IFERROR(H13/ABS(H22),0) | I30: =IFERROR(I13/ABS(I22),0) | J30: =IFERROR(J13/ABS(J22),0) | ... N30: =IFERROR(N13/ABS(N22),0)
B31: Portfolio CAC (£) | C31: =IFERROR(ABS(C22)/C17,0) | D31: =IFERROR(ABS(D22)/D17,0) | E31: =IFERROR(ABS(E22)/E17,0) | F31: =IFERROR(ABS(F22)/F17,0) | G31: =IFERROR(ABS(G22)/G17,0) | H31: =IFERROR(ABS(H22)/H17,0) | I31: =IFERROR(ABS(I22)/I17,0) | J31: =IFERROR(ABS(J22)/J17,0) | ... N31: =IFERROR(ABS(N22)/N17,0)
B32: Revenue per Visitor (£) | C32: =IFERROR(C13/C16,0) | D32: =IFERROR(D13/D16,0) | E32: =IFERROR(E13/E16,0) | F32: =IFERROR(F13/F16,0) | G32: =IFERROR(G13/G16,0) | H32: =IFERROR(H13/H16,0) | I32: =IFERROR(I13/I16,0) | J32: =IFERROR(J13/J16,0) | ... N32: =IFERROR(N13/N16,0)
B34: 12-MONTH TOTALS
B35: Total Revenue | C35: =SUM(C13:N13)
B36: Total Orders | C36: =SUM(C17:N17)
B37: Total Gross Profit | C37: =SUM(C21:N21)
B38: Total Marketing Spend | C38: =SUM(C22:N22)
B39: Total Contribution | C39: =SUM(C26:N26)

Sheet Operations
B2: OPERATIONAL PLAN & TEAM STRUCTURE
B3: Resource Planning, Responsibilities, and Key Milestones
B5: TEAM STRUCTURE & RESPONSIBILITIES
B7: Role | C7: FTE | D7: Monthly Cost | E7: M1-3 | F7: M4-6 | G7: M7-9 | H7: M10-12 | I7: Key Responsibilities
B8: E-commerce Manager | C8: 1 | D8: 4500 | E8: 1 | F8: 1 | G8: 1 | H8: 1 | I8: Strategy, P&L, team leadership, vendor management
B9: Digital Marketing Manager | C9: 1 | D9: 3800 | E9: 1 | F9: 1 | G9: 1 | H9: 1 | I9: Paid campaigns, SEO, email, analytics, ROAS optimization
B10: Content Manager | C10: 1 | D10: 3200 | E10: 0.5 | F10: 1 | G10: 1 | H10: 1 | I10: Product content, blog, social, brand voice
B11: Web Developer | C11: 1 | D11: 4000 | E11: 1 | F11: 1 | G11: 1 | H11: 1 | I11: Site maintenance, CRO, technical SEO, integrations
B12: Customer Service Lead | C12: 1 | D12: 2800 | E12: 0.5 | F12: 0.5 | G12: 1 | H12: 1 | I12: Support team, returns, customer satisfaction
B13: Customer Service Rep | C13: 1 | D13: 2200 | E13: 0 | F13: 0.5 | G13: 1 | H13: 1 | I13: Order support, inquiries, live chat
B14: PPC Specialist | C14: 0.5 | D14: 2500 | E14: 0 | F14: 0.5 | G14: 0.5 | H14: 0.5 | I14: Google Ads, Meta Ads, campaign optimization
B15: SEO Specialist | C15: 0.5 | D15: 2200 | E15: 0.5 | F15: 0.5 | G15: 0.5 | H15: 0.5 | I15: Technical SEO, link building, content strategy
B16: Data Analyst | C16: 0.5 | D16: 2800 | E16: 0 | F16: 0 | G16: 0.5 | H16: 0.5 | I16: Reporting, insights, forecasting, dashboarding
B17: Total Team Cost (Monthly) | D17: =SUM(D8:D16)
B20: KEY MILESTONES & TIMELINE
B22: Phase | C22: Timeline | D22: Key Activities | E22: Success Metrics | F22: Owner
B23: Phase 1: Foundation | C23: M1-M3 | D23: • Site audits & technical fixes • Analytics setup & tracking • Initial content optimization • PPC campaign launch • Team onboarding | E23: • All sites tracking correctly • 0 major technical issues • First campaigns live • Team fully operational | F23: E-commerce Manager
B24: Phase 2: Growth | C24: M4-M6 | D24: • Scale winning campaigns • SEO content expansion • Email automation setup • CRO testing program • Review generation | E24: • ROAS >2.5x • Organic traffic +50% • Email list 1000+ • Conv rate +0.5% | F24: Digital Marketing Manager
B25: Phase 3: Optimization | C25: M7-M9 | D25: • Advanced segmentation • Personalization rollout • Retargeting expansion • Affiliate program launch • International expansion | E25: • ROAS >3.5x • CAC <£25 • Repeat rate >20% • 3 sites profitable | F25: E-commerce Manager
B26: Phase 4: Scale | C26: M10-M12 | D26: • Full budget deployment • New market testing • Product expansion • Automation at scale • Annual planning | E26: • Portfolio ROAS >4x • All sites profitable • £200K+ monthly revenue • 15%+ net margin | F26: E-commerce Manager
B29: MARKETING CHANNEL STRATEGY BY SITE
B31: Site | C31: Primary Channels | D31: Secondary Channels | E31: Budget Split | F31: Focus
B32: GTSE.co.uk | C32: Google Ads (Search), SEO | D32: Email, LinkedIn | E32: 60% Paid, 40% Organic | F32: B2B lead quality
B33: GTSEGroup.com | C33: LinkedIn, Content Marketing | D33: SEO, Email | E33: 40% Paid, 60% Organic | F33: Brand awareness
B34: SSH UK | C34: Google Ads, Facebook | D34: SEO, Email | E34: 70% Paid, 30% Organic | F34: Volume & speed
B35: SSH USA | C35: Google Ads, Facebook, Amazon | D35: SEO, Influencers | E35: 75% Paid, 25% Organic | F35: Market penetration
B36: Epha.com | C36: Content, SEO, PR | D36: LinkedIn, Email | E36: 30% Paid, 70% Organic | F36: Premium positioning
B39: REQUIRED TOOLS & SOFTWARE
B41: Category | C41: Tool | D41: Monthly Cost | E41: Purpose | F41: Sites
B42: Analytics | C42: Google Analytics 4 + Data Studio | D42: 0 | E42: Traffic & conversion tracking | F42: All
B43: Analytics | C43: Hotjar | D43: 99 | E43: Heatmaps & session recordings | F43: All
B44: Email | C44: Klaviyo | D44: 300 | E44: Email marketing automation | F44: All
B45: SEO | C45: SEMrush | D45: 200 | E45: Keyword research & tracking | F45: All
B46: SEO | C46: Ahrefs | D46: 200 | E46: Backlink analysis | F46: All
B47: PPC | C47: Optmyzr | D47: 250 | E47: PPC optimization | F47: SSH sites
B48: CRO | C48: VWO | D48: 150 | E48: A/B testing platform | F48: GTSE.co.uk, SSH
B49: Reviews | C49: Trustpilot | D49: 200 | E49: Review collection | F49: SSH UK, SSH USA
B50: Inventory | C50: Linnworks | D50: 300 | E50: Inventory management | F50: All
B51: Support | C51: Zendesk | D51: 150 | E51: Customer support ticketing | F51: All
B52: Total Tool Costs | C52: (Included in site projections) | D52: =SUM(D42:D51)

Sheet Glossary
B2: E-COMMERCE METRICS GLOSSARY
B3: A comprehensive guide to understanding e-commerce KPIs and financial metrics
B5: HOW TO USE THIS SPREADSHEET
B7: 1. START WITH ASSUMPTIONS: Review and adjust the blue-colored input values in the Assumptions sheet to match your expectations.
B8: 2. REVIEW SITE PROJECTIONS: Each site has its own sheet showing 12-month projections for traffic, revenue, and profitability.
B9: 3. CHECK CONSOLIDATED VIEW: See the portfolio-wide aggregated metrics and track overall performance.
B10: 4. MONITOR MONTHLY: Update actual figures against projections to track variance and adjust strategy.
B11: 5. COLOR CODING: Blue text = Editable inputs | Black text = Calculated values | Green text = Cross-sheet references
B13: TRAFFIC METRICS
B15: Metric | C15: Definition & Calculation | D15: Benchmark | E15: Why It Matters
B16: Organic Traffic | C16: Visitors who find your site through unpaid search results (Google, Bing). Grows through SEO efforts. | D16: 15-30% monthly growth for new sites | E16: Sustainable, low-cost acquisition channel
B17: Paid Traffic | C17: Visitors from paid advertising (Google Ads, Meta/Facebook Ads). Directly controlled by budget. | D17: Varies by industry: £1-5 CPC typical | E17: Immediate traffic, scalable with budget
B18: Direct Traffic | C18: Visitors who type your URL directly or use bookmarks. Indicates brand awareness. | D18: Typically 10-20% of total traffic | E18: Shows brand strength and customer loyalty
B19: Total Traffic | C19: Sum of all traffic sources: Organic + Paid + Direct + Referral + Social. | D19: Growth rate is key metric | E19: Top of funnel - drives all downstream metrics
B20: Bounce Rate | C20: Percentage of visitors who leave after viewing only one page. | D20: Good: <40%, Poor: >60% | E20: Indicates landing page quality and relevance
B22: CONVERSION METRICS
B24: Metric | C24: Definition & Calculation | D24: Benchmark | E24: Why It Matters
B25: Conversion Rate (CVR) | C25: Percentage of visitors who make a purchase. Formula: Orders ÷ Total Traffic × 100 | D25: B2C: 1.5-3%, B2B: 2-5% | E25: Core metric for site effectiveness
B26: Orders | C26: Total number of transactions completed in a period. | D26: Growth rate matters more than absolute | E26: Directly drives revenue
B27: Average Order Value (AOV) | C27: Average amount spent per order. Formula: Revenue ÷ Orders | D27: Varies widely: £50-300 typical | E27: Higher AOV = more revenue per customer
B28: Cart Abandonment Rate | C28: Percentage of shoppers who add items but don't complete purchase. | D28: Industry avg: 70% (lower is better) | E28: Indicates checkout friction
B29: Add to Cart Rate | C29: Percentage of visitors who add items to cart. | D29: Good: >8%, Excellent: >12% | E29: Shows product appeal and pricing
B31: FINANCIAL METRICS
B33: Metric | C33: Definition & Calculation | D33: Benchmark | E33: Why It Matters
B34: Revenue | C34: Total income from sales. Formula: Orders × AOV | D34: Monthly growth target: 10-20% | E34: Top-line business performance
B35: Gross Profit | C35: Revenue minus cost of goods sold. Formula: Revenue × Gross Margin % | D35: Margin % is key: 30-50% typical | E35: Money available to cover operating costs
B36: Gross Margin % | C36: Percentage of revenue kept after product costs. Formula: Gross Profit ÷ Revenue | D36: Good: >35%, Excellent: >50% | E36: Indicates pricing power and efficiency
B37: Contribution | C37: Gross profit minus marketing and operational costs. Shows true profitability per site. | D37: Target: Positive by month 6-9 | E37: Site-level profitability metric
B38: ROAS (Return on Ad Spend) | C38: Revenue generated per £1 spent on ads. Formula: Revenue ÷ Ad Spend | D38: Good: 3x+, Excellent: 5x+ | E38: Measures advertising efficiency
B39: CAC (Customer Acquisition Cost) | C39: Cost to acquire one customer. Formula: Marketing Spend ÷ New Customers | D39: Varies: £10-50 typical | E39: Lower CAC = more efficient marketing
B40: LTV (Lifetime Value) | C40: Total revenue expected from a customer over their relationship. | D40: LTV:CAC ratio should be >3:1 | E40: Justifies acquisition spend
B41: Payback Period | C41: Time to recover CAC through customer purchases. | D41: Good: <6 months | E41: Cash flow critical metric
B43: MARKETING & SEO METRICS
B45: Metric | C45: Definition & Calculation | D45: Benchmark | E45: Why It Matters
B46: CPC (Cost Per Click) | C46: Amount paid for each ad click. Formula: Ad Spend ÷ Clicks | D46: £1-3 typical, varies by industry | E46: Efficiency of paid campaigns
B47: CPM (Cost Per Mille) | C47: Cost per 1,000 ad impressions. | D47: £5-20 typical | E47: Brand awareness campaigns
B48: CTR (Click-Through Rate) | C48: Percentage who click after seeing an ad. Formula: Clicks ÷ Impressions | D48: Good: >2%, Excellent: >5% | E48: Ad relevance and creative quality
B49: Impression Share | C49: Percentage of available impressions your ads received. | D49: Target: >70% for core keywords | E49: Market visibility
B50: Quality Score | C50: Google Ads rating of ad relevance (1-10). | D50: Target: 7+ | E50: Affects CPC and ad position
B51: Domain Authority | C51: SEO score predicting search ranking potential (1-100). | D51: Good: >40, Excellent: >60 | E51: SEO strength indicator
...
